[2024-05-29T17:34:05.478+0000] {taskinstance.py:1956} INFO - Dependencies all met for dep_context=non-requeueable deps ti=<TaskInstance: tipico_database_dag.create_database_redshift manual__2024-05-29T17:34:02.537353+00:00 [queued]>
[2024-05-29T17:34:05.495+0000] {taskinstance.py:1956} INFO - Dependencies all met for dep_context=requeueable deps ti=<TaskInstance: tipico_database_dag.create_database_redshift manual__2024-05-29T17:34:02.537353+00:00 [queued]>
[2024-05-29T17:34:05.496+0000] {taskinstance.py:2170} INFO - Starting attempt 1 of 2
[2024-05-29T17:34:05.521+0000] {taskinstance.py:2191} INFO - Executing <Task(PythonOperator): create_database_redshift> on 2024-05-29 17:34:02.537353+00:00
[2024-05-29T17:34:05.531+0000] {standard_task_runner.py:60} INFO - Started process 6184 to run task
[2024-05-29T17:34:05.538+0000] {standard_task_runner.py:87} INFO - Running: ['***', 'tasks', 'run', 'tipico_database_dag', 'create_database_redshift', 'manual__2024-05-29T17:34:02.537353+00:00', '--job-id', '227', '--raw', '--subdir', 'DAGS_FOLDER/tipico_database_dag.py', '--cfg-path', '/tmp/tmp5l5esz14']
[2024-05-29T17:34:05.543+0000] {standard_task_runner.py:88} INFO - Job 227: Subtask create_database_redshift
[2024-05-29T17:34:05.640+0000] {task_command.py:423} INFO - Running <TaskInstance: tipico_database_dag.create_database_redshift manual__2024-05-29T17:34:02.537353+00:00 [running]> on host f167e9c2a292
[2024-05-29T17:34:05.771+0000] {taskinstance.py:2480} INFO - Exporting env vars: AIRFLOW_CTX_DAG_OWNER='***' AIRFLOW_CTX_DAG_ID='tipico_database_dag' AIRFLOW_CTX_TASK_ID='create_database_redshift' AIRFLOW_CTX_EXECUTION_DATE='2024-05-29T17:34:02.537353+00:00' AIRFLOW_CTX_TRY_NUMBER='1' AIRFLOW_CTX_DAG_RUN_ID='manual__2024-05-29T17:34:02.537353+00:00'
[2024-05-29T17:34:05.785+0000] {base.py:83} INFO - Using connection ID 'redshift_default' for task execution.
[2024-05-29T17:34:06.733+0000] {warnings.py:109} WARNING - /opt/***/dags/tipico_databse.py:43: UserWarning: DB-API extension cursor.connection used
  cursor.execute(sql)

[2024-05-29T17:34:06.736+0000] {taskinstance.py:2698} ERROR - Task failed with exception
Traceback (most recent call last):
  File "/home/airflow/.local/lib/python3.8/site-packages/airflow/models/taskinstance.py", line 433, in _execute_task
    result = execute_callable(context=context, **execute_callable_kwargs)
  File "/home/airflow/.local/lib/python3.8/site-packages/airflow/operators/python.py", line 199, in execute
    return_value = self.execute_callable()
  File "/home/airflow/.local/lib/python3.8/site-packages/airflow/operators/python.py", line 216, in execute_callable
    return self.python_callable(*self.op_args, **self.op_kwargs)
  File "/opt/airflow/dags/tipico_databse.py", line 43, in create_database_redshift
    cursor.execute(sql)
  File "/home/airflow/.local/lib/python3.8/site-packages/redshift_connector/cursor.py", line 248, in execute
    raise e
  File "/home/airflow/.local/lib/python3.8/site-packages/redshift_connector/cursor.py", line 241, in execute
    self._c.execute(self, operation, args)
  File "/home/airflow/.local/lib/python3.8/site-packages/redshift_connector/core.py", line 1959, in execute
    self.handle_messages(cursor)
  File "/home/airflow/.local/lib/python3.8/site-packages/redshift_connector/core.py", line 2166, in handle_messages
    raise self.error
redshift_connector.error.ProgrammingError: {'S': 'ERROR', 'C': '42P07', 'M': 'Relation "events" already exists', 'F': '../src/pg/src/backend/tcop/utility.c', 'L': '234', 'R': 'CheckTableNonExistence'}
[2024-05-29T17:34:06.750+0000] {taskinstance.py:1138} INFO - Marking task as UP_FOR_RETRY. dag_id=tipico_database_dag, task_id=create_database_redshift, execution_date=20240529T173402, start_date=20240529T173405, end_date=20240529T173406
[2024-05-29T17:34:06.778+0000] {standard_task_runner.py:107} ERROR - Failed to execute job 227 for task create_database_redshift ({'S': 'ERROR', 'C': '42P07', 'M': 'Relation "events" already exists', 'F': '../src/pg/src/backend/tcop/utility.c', 'L': '234', 'R': 'CheckTableNonExistence'}; 6184)
[2024-05-29T17:34:06.837+0000] {local_task_job_runner.py:234} INFO - Task exited with return code 1
[2024-05-29T17:34:06.878+0000] {taskinstance.py:3280} INFO - 0 downstream tasks scheduled from follow-on schedule check
