[2024-05-31T02:52:00.024+0000] {taskinstance.py:1956} INFO - Dependencies all met for dep_context=non-requeueable deps ti=<TaskInstance: tipico_dag.load_data_to_redshift manual__2024-05-31T02:51:54.789112+00:00 [queued]>
[2024-05-31T02:52:00.043+0000] {taskinstance.py:1956} INFO - Dependencies all met for dep_context=requeueable deps ti=<TaskInstance: tipico_dag.load_data_to_redshift manual__2024-05-31T02:51:54.789112+00:00 [queued]>
[2024-05-31T02:52:00.044+0000] {taskinstance.py:2170} INFO - Starting attempt 1 of 2
[2024-05-31T02:52:00.069+0000] {taskinstance.py:2191} INFO - Executing <Task(PythonOperator): load_data_to_redshift> on 2024-05-31 02:51:54.789112+00:00
[2024-05-31T02:52:00.079+0000] {standard_task_runner.py:60} INFO - Started process 25210 to run task
[2024-05-31T02:52:00.084+0000] {standard_task_runner.py:87} INFO - Running: ['***', 'tasks', 'run', 'tipico_dag', 'load_data_to_redshift', 'manual__2024-05-31T02:51:54.789112+00:00', '--job-id', '256', '--raw', '--subdir', 'DAGS_FOLDER/tipico_dag.py', '--cfg-path', '/tmp/tmpdg3dvvwv']
[2024-05-31T02:52:00.086+0000] {standard_task_runner.py:88} INFO - Job 256: Subtask load_data_to_redshift
[2024-05-31T02:52:00.147+0000] {task_command.py:423} INFO - Running <TaskInstance: tipico_dag.load_data_to_redshift manual__2024-05-31T02:51:54.789112+00:00 [running]> on host a71bb5ce980f
[2024-05-31T02:52:00.234+0000] {taskinstance.py:2480} INFO - Exporting env vars: AIRFLOW_CTX_DAG_OWNER='***' AIRFLOW_CTX_DAG_ID='tipico_dag' AIRFLOW_CTX_TASK_ID='load_data_to_redshift' AIRFLOW_CTX_EXECUTION_DATE='2024-05-31T02:51:54.789112+00:00' AIRFLOW_CTX_TRY_NUMBER='1' AIRFLOW_CTX_DAG_RUN_ID='manual__2024-05-31T02:51:54.789112+00:00'
[2024-05-31T02:52:00.241+0000] {taskinstance.py:2698} ERROR - Task failed with exception
Traceback (most recent call last):
  File "/home/airflow/.local/lib/python3.8/site-packages/airflow/models/taskinstance.py", line 433, in _execute_task
    result = execute_callable(context=context, **execute_callable_kwargs)
  File "/home/airflow/.local/lib/python3.8/site-packages/airflow/operators/python.py", line 199, in execute
    return_value = self.execute_callable()
  File "/home/airflow/.local/lib/python3.8/site-packages/airflow/operators/python.py", line 216, in execute_callable
    return self.python_callable(*self.op_args, **self.op_kwargs)
  File "/opt/airflow/dags/tipico_etl.py", line 27, in load_data_to_redshift
    df = pd.read_csv(filename)
  File "/home/airflow/.local/lib/python3.8/site-packages/pandas/io/parsers/readers.py", line 912, in read_csv
    return _read(filepath_or_buffer, kwds)
  File "/home/airflow/.local/lib/python3.8/site-packages/pandas/io/parsers/readers.py", line 577, in _read
    parser = TextFileReader(filepath_or_buffer, **kwds)
  File "/home/airflow/.local/lib/python3.8/site-packages/pandas/io/parsers/readers.py", line 1407, in __init__
    self._engine = self._make_engine(f, self.engine)
  File "/home/airflow/.local/lib/python3.8/site-packages/pandas/io/parsers/readers.py", line 1661, in _make_engine
    self.handles = get_handle(
  File "/home/airflow/.local/lib/python3.8/site-packages/pandas/io/common.py", line 859, in get_handle
    handle = open(
FileNotFoundError: [Errno 2] No such file or directory: './data/tipico_data_202405310252.csv'
[2024-05-31T02:52:00.264+0000] {taskinstance.py:1138} INFO - Marking task as UP_FOR_RETRY. dag_id=tipico_dag, task_id=load_data_to_redshift, execution_date=20240531T025154, start_date=20240531T025200, end_date=20240531T025200
[2024-05-31T02:52:00.282+0000] {standard_task_runner.py:107} ERROR - Failed to execute job 256 for task load_data_to_redshift ([Errno 2] No such file or directory: './data/tipico_data_202405310252.csv'; 25210)
[2024-05-31T02:52:00.299+0000] {local_task_job_runner.py:234} INFO - Task exited with return code 1
[2024-05-31T02:52:00.324+0000] {taskinstance.py:3280} INFO - 0 downstream tasks scheduled from follow-on schedule check
