[2024-05-30T08:00:02.244+0000] {taskinstance.py:1956} INFO - Dependencies all met for dep_context=non-requeueable deps ti=<TaskInstance: tipico_dag.fetch_tipico_data scheduled__2024-05-30T07:50:00+00:00 [queued]>
[2024-05-30T08:00:02.256+0000] {taskinstance.py:1956} INFO - Dependencies all met for dep_context=requeueable deps ti=<TaskInstance: tipico_dag.fetch_tipico_data scheduled__2024-05-30T07:50:00+00:00 [queued]>
[2024-05-30T08:00:02.258+0000] {taskinstance.py:2170} INFO - Starting attempt 1 of 2
[2024-05-30T08:00:02.277+0000] {taskinstance.py:2191} INFO - Executing <Task(PythonOperator): fetch_tipico_data> on 2024-05-30 07:50:00+00:00
[2024-05-30T08:00:02.287+0000] {standard_task_runner.py:60} INFO - Started process 7726 to run task
[2024-05-30T08:00:02.293+0000] {standard_task_runner.py:87} INFO - Running: ['***', 'tasks', 'run', 'tipico_dag', 'fetch_tipico_data', 'scheduled__2024-05-30T07:50:00+00:00', '--job-id', '54', '--raw', '--subdir', 'DAGS_FOLDER/tipico_dag.py', '--cfg-path', '/tmp/tmpv00o7blo']
[2024-05-30T08:00:02.296+0000] {standard_task_runner.py:88} INFO - Job 54: Subtask fetch_tipico_data
[2024-05-30T08:00:02.382+0000] {task_command.py:423} INFO - Running <TaskInstance: tipico_dag.fetch_tipico_data scheduled__2024-05-30T07:50:00+00:00 [running]> on host a71bb5ce980f
[2024-05-30T08:00:02.472+0000] {taskinstance.py:2480} INFO - Exporting env vars: AIRFLOW_CTX_DAG_OWNER='***' AIRFLOW_CTX_DAG_ID='tipico_dag' AIRFLOW_CTX_TASK_ID='fetch_tipico_data' AIRFLOW_CTX_EXECUTION_DATE='2024-05-30T07:50:00+00:00' AIRFLOW_CTX_TRY_NUMBER='1' AIRFLOW_CTX_DAG_RUN_ID='scheduled__2024-05-30T07:50:00+00:00'
[2024-05-30T08:00:06.485+0000] {taskinstance.py:2698} ERROR - Task failed with exception
Traceback (most recent call last):
  File "/home/airflow/.local/lib/python3.8/site-packages/urllib3/connection.py", line 174, in _new_conn
    conn = connection.create_connection(
  File "/home/airflow/.local/lib/python3.8/site-packages/urllib3/util/connection.py", line 72, in create_connection
    for res in socket.getaddrinfo(host, port, family, socket.SOCK_STREAM):
  File "/usr/local/lib/python3.8/socket.py", line 918, in getaddrinfo
    for res in _socket.getaddrinfo(host, port, family, type, proto, flags):
socket.gaierror: [Errno -5] No address associated with hostname

During handling of the above exception, another exception occurred:

Traceback (most recent call last):
  File "/home/airflow/.local/lib/python3.8/site-packages/urllib3/connectionpool.py", line 715, in urlopen
    httplib_response = self._make_request(
  File "/home/airflow/.local/lib/python3.8/site-packages/urllib3/connectionpool.py", line 404, in _make_request
    self._validate_conn(conn)
  File "/home/airflow/.local/lib/python3.8/site-packages/urllib3/connectionpool.py", line 1058, in _validate_conn
    conn.connect()
  File "/home/airflow/.local/lib/python3.8/site-packages/urllib3/connection.py", line 363, in connect
    self.sock = conn = self._new_conn()
  File "/home/airflow/.local/lib/python3.8/site-packages/urllib3/connection.py", line 186, in _new_conn
    raise NewConnectionError(
urllib3.exceptions.NewConnectionError: <urllib3.connection.HTTPSConnection object at 0x7f4e5dbb37c0>: Failed to establish a new connection: [Errno -5] No address associated with hostname

During handling of the above exception, another exception occurred:

Traceback (most recent call last):
  File "/home/airflow/.local/lib/python3.8/site-packages/requests/adapters.py", line 486, in send
    resp = conn.urlopen(
  File "/home/airflow/.local/lib/python3.8/site-packages/urllib3/connectionpool.py", line 799, in urlopen
    retries = retries.increment(
  File "/home/airflow/.local/lib/python3.8/site-packages/urllib3/util/retry.py", line 592, in increment
    raise MaxRetryError(_pool, url, error or ResponseError(cause))
urllib3.exceptions.MaxRetryError: HTTPSConnectionPool(host='trading-api.tipico.us', port=443): Max retries exceeded with url: /v1/pds/lbc/events/live?licenseId=US-NJ&lang=en&limit=18 (Caused by NewConnectionError('<urllib3.connection.HTTPSConnection object at 0x7f4e5dbb37c0>: Failed to establish a new connection: [Errno -5] No address associated with hostname'))

During handling of the above exception, another exception occurred:

Traceback (most recent call last):
  File "/home/airflow/.local/lib/python3.8/site-packages/airflow/models/taskinstance.py", line 433, in _execute_task
    result = execute_callable(context=context, **execute_callable_kwargs)
  File "/home/airflow/.local/lib/python3.8/site-packages/airflow/operators/python.py", line 199, in execute
    return_value = self.execute_callable()
  File "/home/airflow/.local/lib/python3.8/site-packages/airflow/operators/python.py", line 216, in execute_callable
    return self.python_callable(*self.op_args, **self.op_kwargs)
  File "/opt/airflow/dags/tipico_etl.py", line 12, in fetch_tipico_data
    response = requests.get(url)
  File "/home/airflow/.local/lib/python3.8/site-packages/requests/api.py", line 73, in get
    return request("get", url, params=params, **kwargs)
  File "/home/airflow/.local/lib/python3.8/site-packages/requests/api.py", line 59, in request
    return session.request(method=method, url=url, **kwargs)
  File "/home/airflow/.local/lib/python3.8/site-packages/requests/sessions.py", line 589, in request
    resp = self.send(prep, **send_kwargs)
  File "/home/airflow/.local/lib/python3.8/site-packages/requests/sessions.py", line 703, in send
    r = adapter.send(request, **kwargs)
  File "/home/airflow/.local/lib/python3.8/site-packages/requests/adapters.py", line 519, in send
    raise ConnectionError(e, request=request)
requests.exceptions.ConnectionError: HTTPSConnectionPool(host='trading-api.tipico.us', port=443): Max retries exceeded with url: /v1/pds/lbc/events/live?licenseId=US-NJ&lang=en&limit=18 (Caused by NewConnectionError('<urllib3.connection.HTTPSConnection object at 0x7f4e5dbb37c0>: Failed to establish a new connection: [Errno -5] No address associated with hostname'))
[2024-05-30T08:00:06.509+0000] {taskinstance.py:1138} INFO - Marking task as UP_FOR_RETRY. dag_id=tipico_dag, task_id=fetch_tipico_data, execution_date=20240530T075000, start_date=20240530T080002, end_date=20240530T080006
[2024-05-30T08:00:06.527+0000] {standard_task_runner.py:107} ERROR - Failed to execute job 54 for task fetch_tipico_data (HTTPSConnectionPool(host='trading-api.tipico.us', port=443): Max retries exceeded with url: /v1/pds/lbc/events/live?licenseId=US-NJ&lang=en&limit=18 (Caused by NewConnectionError('<urllib3.connection.HTTPSConnection object at 0x7f4e5dbb37c0>: Failed to establish a new connection: [Errno -5] No address associated with hostname')); 7726)
[2024-05-30T08:00:06.536+0000] {local_task_job_runner.py:234} INFO - Task exited with return code 1
[2024-05-30T08:00:06.558+0000] {taskinstance.py:3280} INFO - 0 downstream tasks scheduled from follow-on schedule check
