[2024-05-27T23:35:14.461+0000] {taskinstance.py:1956} INFO - Dependencies all met for dep_context=non-requeueable deps ti=<TaskInstance: tipico_dag.run_tipico_etl scheduled__2024-05-27T23:20:00+00:00 [queued]>
[2024-05-27T23:35:14.481+0000] {taskinstance.py:1956} INFO - Dependencies all met for dep_context=requeueable deps ti=<TaskInstance: tipico_dag.run_tipico_etl scheduled__2024-05-27T23:20:00+00:00 [queued]>
[2024-05-27T23:35:14.482+0000] {taskinstance.py:2170} INFO - Starting attempt 1 of 2
[2024-05-27T23:35:14.507+0000] {taskinstance.py:2191} INFO - Executing <Task(PythonOperator): run_tipico_etl> on 2024-05-27 23:20:00+00:00
[2024-05-27T23:35:14.518+0000] {standard_task_runner.py:60} INFO - Started process 194 to run task
[2024-05-27T23:35:14.523+0000] {standard_task_runner.py:87} INFO - Running: ['***', 'tasks', 'run', 'tipico_dag', 'run_tipico_etl', 'scheduled__2024-05-27T23:20:00+00:00', '--job-id', '138', '--raw', '--subdir', 'DAGS_FOLDER/tipico_dag.py', '--cfg-path', '/tmp/tmplpzvj1dc']
[2024-05-27T23:35:14.526+0000] {standard_task_runner.py:88} INFO - Job 138: Subtask run_tipico_etl
[2024-05-27T23:35:14.598+0000] {task_command.py:423} INFO - Running <TaskInstance: tipico_dag.run_tipico_etl scheduled__2024-05-27T23:20:00+00:00 [running]> on host f167e9c2a292
[2024-05-27T23:35:14.723+0000] {taskinstance.py:2480} INFO - Exporting env vars: AIRFLOW_CTX_DAG_OWNER='***' AIRFLOW_CTX_DAG_ID='tipico_dag' AIRFLOW_CTX_TASK_ID='run_tipico_etl' AIRFLOW_CTX_EXECUTION_DATE='2024-05-27T23:20:00+00:00' AIRFLOW_CTX_TRY_NUMBER='1' AIRFLOW_CTX_DAG_RUN_ID='scheduled__2024-05-27T23:20:00+00:00'
[2024-05-27T23:35:14.739+0000] {taskinstance.py:2698} ERROR - Task failed with exception
Traceback (most recent call last):
  File "/home/airflow/.local/lib/python3.8/site-packages/urllib3/connection.py", line 174, in _new_conn
    conn = connection.create_connection(
  File "/home/airflow/.local/lib/python3.8/site-packages/urllib3/util/connection.py", line 72, in create_connection
    for res in socket.getaddrinfo(host, port, family, socket.SOCK_STREAM):
  File "/usr/local/lib/python3.8/socket.py", line 918, in getaddrinfo
    for res in _socket.getaddrinfo(host, port, family, type, proto, flags):
socket.gaierror: [Errno -2] Name or service not known

During handling of the above exception, another exception occurred:

Traceback (most recent call last):
  File "/home/airflow/.local/lib/python3.8/site-packages/urllib3/connectionpool.py", line 715, in urlopen
    httplib_response = self._make_request(
  File "/home/airflow/.local/lib/python3.8/site-packages/urllib3/connectionpool.py", line 404, in _make_request
    self._validate_conn(conn)
  File "/home/airflow/.local/lib/python3.8/site-packages/urllib3/connectionpool.py", line 1058, in _validate_conn
    conn.connect()
  File "/home/airflow/.local/lib/python3.8/site-packages/urllib3/connection.py", line 363, in connect
    self.sock = conn = self._new_conn()
  File "/home/airflow/.local/lib/python3.8/site-packages/urllib3/connection.py", line 186, in _new_conn
    raise NewConnectionError(
urllib3.exceptions.NewConnectionError: <urllib3.connection.HTTPSConnection object at 0x7fd0b7f7dca0>: Failed to establish a new connection: [Errno -2] Name or service not known

During handling of the above exception, another exception occurred:

Traceback (most recent call last):
  File "/home/airflow/.local/lib/python3.8/site-packages/requests/adapters.py", line 486, in send
    resp = conn.urlopen(
  File "/home/airflow/.local/lib/python3.8/site-packages/urllib3/connectionpool.py", line 799, in urlopen
    retries = retries.increment(
  File "/home/airflow/.local/lib/python3.8/site-packages/urllib3/util/retry.py", line 592, in increment
    raise MaxRetryError(_pool, url, error or ResponseError(cause))
urllib3.exceptions.MaxRetryError: HTTPSConnectionPool(host='trading-api.tipico.us', port=443): Max retries exceeded with url: /v1/pds/lbc/events/live?licenseId=US-NJ&lang=en&limit=18 (Caused by NewConnectionError('<urllib3.connection.HTTPSConnection object at 0x7fd0b7f7dca0>: Failed to establish a new connection: [Errno -2] Name or service not known'))

During handling of the above exception, another exception occurred:

Traceback (most recent call last):
  File "/home/airflow/.local/lib/python3.8/site-packages/airflow/models/taskinstance.py", line 433, in _execute_task
    result = execute_callable(context=context, **execute_callable_kwargs)
  File "/home/airflow/.local/lib/python3.8/site-packages/airflow/operators/python.py", line 199, in execute
    return_value = self.execute_callable()
  File "/home/airflow/.local/lib/python3.8/site-packages/airflow/operators/python.py", line 216, in execute_callable
    return self.python_callable(*self.op_args, **self.op_kwargs)
  File "/opt/airflow/dags/tipico_etl.py", line 11, in run_tipico_etl
    response = requests.get(url)
  File "/home/airflow/.local/lib/python3.8/site-packages/requests/api.py", line 73, in get
    return request("get", url, params=params, **kwargs)
  File "/home/airflow/.local/lib/python3.8/site-packages/requests/api.py", line 59, in request
    return session.request(method=method, url=url, **kwargs)
  File "/home/airflow/.local/lib/python3.8/site-packages/requests/sessions.py", line 589, in request
    resp = self.send(prep, **send_kwargs)
  File "/home/airflow/.local/lib/python3.8/site-packages/requests/sessions.py", line 703, in send
    r = adapter.send(request, **kwargs)
  File "/home/airflow/.local/lib/python3.8/site-packages/requests/adapters.py", line 519, in send
    raise ConnectionError(e, request=request)
requests.exceptions.ConnectionError: HTTPSConnectionPool(host='trading-api.tipico.us', port=443): Max retries exceeded with url: /v1/pds/lbc/events/live?licenseId=US-NJ&lang=en&limit=18 (Caused by NewConnectionError('<urllib3.connection.HTTPSConnection object at 0x7fd0b7f7dca0>: Failed to establish a new connection: [Errno -2] Name or service not known'))
[2024-05-27T23:35:14.768+0000] {taskinstance.py:1138} INFO - Marking task as UP_FOR_RETRY. dag_id=tipico_dag, task_id=run_tipico_etl, execution_date=20240527T232000, start_date=20240527T233514, end_date=20240527T233514
[2024-05-27T23:35:14.795+0000] {standard_task_runner.py:107} ERROR - Failed to execute job 138 for task run_tipico_etl (HTTPSConnectionPool(host='trading-api.tipico.us', port=443): Max retries exceeded with url: /v1/pds/lbc/events/live?licenseId=US-NJ&lang=en&limit=18 (Caused by NewConnectionError('<urllib3.connection.HTTPSConnection object at 0x7fd0b7f7dca0>: Failed to establish a new connection: [Errno -2] Name or service not known')); 194)
[2024-05-27T23:35:14.817+0000] {local_task_job_runner.py:234} INFO - Task exited with return code 1
[2024-05-27T23:35:14.846+0000] {taskinstance.py:3280} INFO - 0 downstream tasks scheduled from follow-on schedule check
