[2024-05-30T06:16:36.782+0000] {taskinstance.py:1956} INFO - Dependencies all met for dep_context=non-requeueable deps ti=<TaskInstance: tipico_dag.load_data_to_redshift manual__2024-05-30T06:16:32.006038+00:00 [queued]>
[2024-05-30T06:16:36.793+0000] {taskinstance.py:1956} INFO - Dependencies all met for dep_context=requeueable deps ti=<TaskInstance: tipico_dag.load_data_to_redshift manual__2024-05-30T06:16:32.006038+00:00 [queued]>
[2024-05-30T06:16:36.793+0000] {taskinstance.py:2170} INFO - Starting attempt 1 of 2
[2024-05-30T06:16:36.811+0000] {taskinstance.py:2191} INFO - Executing <Task(PythonOperator): load_data_to_redshift> on 2024-05-30 06:16:32.006038+00:00
[2024-05-30T06:16:36.821+0000] {standard_task_runner.py:60} INFO - Started process 6040 to run task
[2024-05-30T06:16:36.825+0000] {standard_task_runner.py:87} INFO - Running: ['***', 'tasks', 'run', 'tipico_dag', 'load_data_to_redshift', 'manual__2024-05-30T06:16:32.006038+00:00', '--job-id', '9', '--raw', '--subdir', 'DAGS_FOLDER/tipico_dag.py', '--cfg-path', '/tmp/tmp5osem61h']
[2024-05-30T06:16:36.827+0000] {standard_task_runner.py:88} INFO - Job 9: Subtask load_data_to_redshift
[2024-05-30T06:16:36.923+0000] {task_command.py:423} INFO - Running <TaskInstance: tipico_dag.load_data_to_redshift manual__2024-05-30T06:16:32.006038+00:00 [running]> on host a71bb5ce980f
[2024-05-30T06:16:37.064+0000] {taskinstance.py:2480} INFO - Exporting env vars: AIRFLOW_CTX_DAG_OWNER='***' AIRFLOW_CTX_DAG_ID='tipico_dag' AIRFLOW_CTX_TASK_ID='load_data_to_redshift' AIRFLOW_CTX_EXECUTION_DATE='2024-05-30T06:16:32.006038+00:00' AIRFLOW_CTX_TRY_NUMBER='1' AIRFLOW_CTX_DAG_RUN_ID='manual__2024-05-30T06:16:32.006038+00:00'
[2024-05-30T06:16:37.131+0000] {logging_mixin.py:188} INFO -    Unnamed: 0  ...                              sportCurrentGameState
0           0  ...                                                NaN
1           1  ...  {'updatedAt': '0', 'netSportCurrentGameState':...
2           2  ...  {'updatedAt': '0', 'netSportCurrentGameState':...
3           3  ...  {'updatedAt': '0', 'netSportCurrentGameState':...
4           4  ...  {'updatedAt': '0', 'netSportCurrentGameState':...

[5 rows x 22 columns]
[2024-05-30T06:16:37.149+0000] {base.py:83} INFO - Using connection ID 'redshift_default' for task execution.
[2024-05-30T06:16:38.620+0000] {logging_mixin.py:188} INFO - {816775}
[2024-05-30T06:16:38.621+0000] {taskinstance.py:2698} ERROR - Task failed with exception
Traceback (most recent call last):
  File "/home/airflow/.local/lib/python3.8/site-packages/pandas/core/indexes/base.py", line 3653, in get_loc
    return self._engine.get_loc(casted_key)
  File "pandas/_libs/index.pyx", line 147, in pandas._libs.index.IndexEngine.get_loc
  File "pandas/_libs/index.pyx", line 176, in pandas._libs.index.IndexEngine.get_loc
  File "pandas/_libs/hashtable_class_helper.pxi", line 7080, in pandas._libs.hashtable.PyObjectHashTable.get_item
  File "pandas/_libs/hashtable_class_helper.pxi", line 7088, in pandas._libs.hashtable.PyObjectHashTable.get_item
KeyError: 'groupDetails'

The above exception was the direct cause of the following exception:

Traceback (most recent call last):
  File "/home/airflow/.local/lib/python3.8/site-packages/airflow/models/taskinstance.py", line 433, in _execute_task
    result = execute_callable(context=context, **execute_callable_kwargs)
  File "/home/airflow/.local/lib/python3.8/site-packages/airflow/operators/python.py", line 199, in execute
    return_value = self.execute_callable()
  File "/home/airflow/.local/lib/python3.8/site-packages/airflow/operators/python.py", line 216, in execute_callable
    return self.python_callable(*self.op_args, **self.op_kwargs)
  File "/opt/airflow/dags/tipico_etl.py", line 67, in load_data_to_redshift
    '{row['groupDetails']}'
  File "/home/airflow/.local/lib/python3.8/site-packages/pandas/core/series.py", line 1007, in __getitem__
    return self._get_value(key)
  File "/home/airflow/.local/lib/python3.8/site-packages/pandas/core/series.py", line 1116, in _get_value
    loc = self.index.get_loc(label)
  File "/home/airflow/.local/lib/python3.8/site-packages/pandas/core/indexes/base.py", line 3655, in get_loc
    raise KeyError(key) from err
KeyError: 'groupDetails'
[2024-05-30T06:16:38.672+0000] {taskinstance.py:1138} INFO - Marking task as UP_FOR_RETRY. dag_id=tipico_dag, task_id=load_data_to_redshift, execution_date=20240530T061632, start_date=20240530T061636, end_date=20240530T061638
[2024-05-30T06:16:38.708+0000] {standard_task_runner.py:107} ERROR - Failed to execute job 9 for task load_data_to_redshift ('groupDetails'; 6040)
[2024-05-30T06:16:38.767+0000] {local_task_job_runner.py:234} INFO - Task exited with return code 1
[2024-05-30T06:16:38.798+0000] {taskinstance.py:3280} INFO - 0 downstream tasks scheduled from follow-on schedule check
