[2024-05-31T02:56:14.824+0000] {taskinstance.py:1956} INFO - Dependencies all met for dep_context=non-requeueable deps ti=<TaskInstance: tipico_dag.load_data_to_redshift manual__2024-05-31T02:50:37.831658+00:00 [queued]>
[2024-05-31T02:56:14.834+0000] {taskinstance.py:1956} INFO - Dependencies all met for dep_context=requeueable deps ti=<TaskInstance: tipico_dag.load_data_to_redshift manual__2024-05-31T02:50:37.831658+00:00 [queued]>
[2024-05-31T02:56:14.835+0000] {taskinstance.py:2170} INFO - Starting attempt 2 of 2
[2024-05-31T02:56:14.851+0000] {taskinstance.py:2191} INFO - Executing <Task(PythonOperator): load_data_to_redshift> on 2024-05-31 02:50:37.831658+00:00
[2024-05-31T02:56:14.860+0000] {standard_task_runner.py:60} INFO - Started process 25300 to run task
[2024-05-31T02:56:14.864+0000] {standard_task_runner.py:87} INFO - Running: ['***', 'tasks', 'run', 'tipico_dag', 'load_data_to_redshift', 'manual__2024-05-31T02:50:37.831658+00:00', '--job-id', '263', '--raw', '--subdir', 'DAGS_FOLDER/tipico_dag.py', '--cfg-path', '/tmp/tmp2fygjdt2']
[2024-05-31T02:56:14.866+0000] {standard_task_runner.py:88} INFO - Job 263: Subtask load_data_to_redshift
[2024-05-31T02:56:14.923+0000] {task_command.py:423} INFO - Running <TaskInstance: tipico_dag.load_data_to_redshift manual__2024-05-31T02:50:37.831658+00:00 [running]> on host a71bb5ce980f
[2024-05-31T02:56:15.022+0000] {taskinstance.py:2480} INFO - Exporting env vars: AIRFLOW_CTX_DAG_OWNER='***' AIRFLOW_CTX_DAG_ID='tipico_dag' AIRFLOW_CTX_TASK_ID='load_data_to_redshift' AIRFLOW_CTX_EXECUTION_DATE='2024-05-31T02:50:37.831658+00:00' AIRFLOW_CTX_TRY_NUMBER='2' AIRFLOW_CTX_DAG_RUN_ID='manual__2024-05-31T02:50:37.831658+00:00'
[2024-05-31T02:56:15.084+0000] {logging_mixin.py:188} INFO -    Unnamed: 0  ...  eventMetadata
0           0  ...            NaN
1           1  ...            NaN
2           2  ...            NaN
3           3  ...            NaN
4           4  ...            NaN

[5 rows x 22 columns]
[2024-05-31T02:56:15.097+0000] {base.py:83} INFO - Using connection ID 'redshift_default' for task execution.
[2024-05-31T02:56:15.809+0000] {logging_mixin.py:188} INFO - {814989}
[2024-05-31T02:56:15.964+0000] {warnings.py:109} WARNING - /opt/***/dags/tipico_etl.py:40: UserWarning: DB-API extension cursor.connection used
  cursor.execute(sql)

[2024-05-31T02:56:15.965+0000] {taskinstance.py:2698} ERROR - Task failed with exception
Traceback (most recent call last):
  File "/home/airflow/.local/lib/python3.8/site-packages/redshift_connector/core.py", line 1793, in execute
    ps = cache["ps"][key]
KeyError: ("INSERT INTO vrashi_shrivastava.EVENTS (id, startTime, messageTime, sportType, matchState, participants, status, marketCount, groupDetails, markets, eventType, updatesCount, displayInfo, score, gameClock, eventReferences, eventDetails, sportCurrentGameState, lastModifiedTime, eventTags) \n        VALUES(814989, 2024-05-29T09:00:00Z, 2024-05-30T20:32:20.696Z,'TENNIS', INTERRUPTED,[{'id': 71233, 'name': 'Kato M / Kichenok N', 'position': 'HOME', 'abbreviation': 'KKI'}, {'id': 39274, 'name': 'Saville D / Tomljanovic A', 'position': 'AWAY', 'abbreviation': 'STO'}], RUNNING,1, {'id': 54, 'name': 'French Open Women Doubles', 'parentGroup': {'id': 55, 'name': 'WTA', 'parentGroup': {'id': 21, 'name': 'Tennis'}}},[{'id': 'a85a5cf8-6f94-3d07-baa4-d44f48fc0e9d', 'name': 'Moneyline', 'type': 'standard', 'parameters': [], 'status': 'OPEN', 'mostBalancedLine': True, 'sgpEligable': False, 'outcomes': [{'id': '047fad12-af4d-397a-bb30-e42ba15c96b6', 'name': 'Kato M / Kichenok N', 'isTraded': True, 'formatDecimal': 1.17, 'formatAmerican': '-556', 'status': 'ONGOING', 'trueOdds': 1.179856115}, {'id': '0fe14f6a-3c54-3be6-a01f-bb25cac87ede', 'name': 'Saville D / Tomljanovic A', 'isTraded': True, 'formatDecimal': 4.0, 'formatAmerican': '300', 'status': 'ONGOING', 'trueOdds': 4.0}]}], MATCH,235, {},{'total': {'home': {'sets': 0, 'games': 5, 'points': '0'}, 'away': {'sets': 0, 'games': 2, 'points': '0'}}, 'sections': [{'section': 1, 'home': {'sets': 0, 'games': 5, 'points': '0'}, 'away': {'sets': 0, 'games': 2, 'points': '0'}}]}, {'clockType': 'SECTIONS', 'eventState': 'INTERRUPTED', 'sectionNumber': 1, 'techDisplayName': 'SET', 'activeParticipant': 'HOME', 'firstServer': 'AWAY'},[{'providerId': '81', 'eventId': '53829897863524352'}, {'providerId': '84', 'eventId': '53829897863524352'}, {'providerId': '90', 'eventId': '50346431'}, {'providerId': '92', 'eventId': '50346431'}, {'providerId': '102', 'eventId': '50346431'}, {'providerId': '103', 'eventId': '53829897863524352'}, {'providerId': '106', 'eventId': '53829897863524352'}], {'subgroupNameKey': 'French Open Women Doubles, Round_of_64', 'best_of_sets': '3', 'block_cashout': 'false', 'activeParticipant': 'HOME', 'subgroupIdKey': '141672'},{'updatedAt': '0', 'netSportCurrentGameState': {'firstServer': 2, 'currentServer': 1, 'homeFullScore': 0, 'awayFullScore': 0}}, 2024-05-30T20:32:20.840Z,['awayParticipantStateLocation:UNKNOWN', 'venueStateLocation:OTHER', 'homeParticipantStateLocation:UNKNOWN', 'isTradedLive']);", ())

During handling of the above exception, another exception occurred:

Traceback (most recent call last):
  File "/home/airflow/.local/lib/python3.8/site-packages/airflow/models/taskinstance.py", line 433, in _execute_task
    result = execute_callable(context=context, **execute_callable_kwargs)
  File "/home/airflow/.local/lib/python3.8/site-packages/airflow/operators/python.py", line 199, in execute
    return_value = self.execute_callable()
  File "/home/airflow/.local/lib/python3.8/site-packages/airflow/operators/python.py", line 216, in execute_callable
    return self.python_callable(*self.op_args, **self.op_kwargs)
  File "/opt/airflow/dags/tipico_etl.py", line 40, in load_data_to_redshift
    cursor.execute(sql)
  File "/home/airflow/.local/lib/python3.8/site-packages/redshift_connector/cursor.py", line 248, in execute
    raise e
  File "/home/airflow/.local/lib/python3.8/site-packages/redshift_connector/cursor.py", line 241, in execute
    self._c.execute(self, operation, args)
  File "/home/airflow/.local/lib/python3.8/site-packages/redshift_connector/core.py", line 1874, in execute
    self.handle_messages(cursor)
  File "/home/airflow/.local/lib/python3.8/site-packages/redshift_connector/core.py", line 2166, in handle_messages
    raise self.error
redshift_connector.error.ProgrammingError: {'S': 'ERROR', 'C': '42601', 'M': 'syntax error at or near "T09"', 'P': '322', 'F': '/home/ec2-user/padb/src/pg/src/backend/parser/parser_scan.l', 'L': '821', 'R': 'yyerror'}
[2024-05-31T02:56:15.977+0000] {taskinstance.py:1138} INFO - Marking task as FAILED. dag_id=tipico_dag, task_id=load_data_to_redshift, execution_date=20240531T025037, start_date=20240531T025614, end_date=20240531T025615
[2024-05-31T02:56:15.994+0000] {standard_task_runner.py:107} ERROR - Failed to execute job 263 for task load_data_to_redshift ({'S': 'ERROR', 'C': '42601', 'M': 'syntax error at or near "T09"', 'P': '322', 'F': '/home/ec2-user/padb/src/pg/src/backend/parser/parser_scan.l', 'L': '821', 'R': 'yyerror'}; 25300)
[2024-05-31T02:56:16.045+0000] {local_task_job_runner.py:234} INFO - Task exited with return code 1
[2024-05-31T02:56:16.085+0000] {taskinstance.py:3280} INFO - 0 downstream tasks scheduled from follow-on schedule check
