[2024-05-27T17:34:05.215+0000] {taskinstance.py:1956} INFO - Dependencies all met for dep_context=non-requeueable deps ti=<TaskInstance: tipico_dag.run_tipico_etl manual__2024-05-27T17:34:02.589937+00:00 [queued]>
[2024-05-27T17:34:05.226+0000] {taskinstance.py:1956} INFO - Dependencies all met for dep_context=requeueable deps ti=<TaskInstance: tipico_dag.run_tipico_etl manual__2024-05-27T17:34:02.589937+00:00 [queued]>
[2024-05-27T17:34:05.227+0000] {taskinstance.py:2170} INFO - Starting attempt 1 of 2
[2024-05-27T17:34:05.245+0000] {taskinstance.py:2191} INFO - Executing <Task(PythonOperator): run_tipico_etl> on 2024-05-27 17:34:02.589937+00:00
[2024-05-27T17:34:05.252+0000] {standard_task_runner.py:60} INFO - Started process 317 to run task
[2024-05-27T17:34:05.256+0000] {standard_task_runner.py:87} INFO - Running: ['***', 'tasks', 'run', 'tipico_dag', 'run_tipico_etl', 'manual__2024-05-27T17:34:02.589937+00:00', '--job-id', '123', '--raw', '--subdir', 'DAGS_FOLDER/tipico_dag.py', '--cfg-path', '/tmp/tmpbz3236oc']
[2024-05-27T17:34:05.258+0000] {standard_task_runner.py:88} INFO - Job 123: Subtask run_tipico_etl
[2024-05-27T17:34:05.338+0000] {task_command.py:423} INFO - Running <TaskInstance: tipico_dag.run_tipico_etl manual__2024-05-27T17:34:02.589937+00:00 [running]> on host aea090bfdf45
[2024-05-27T17:34:05.432+0000] {taskinstance.py:2480} INFO - Exporting env vars: AIRFLOW_CTX_DAG_OWNER='***' AIRFLOW_CTX_DAG_ID='tipico_dag' AIRFLOW_CTX_TASK_ID='run_tipico_etl' AIRFLOW_CTX_EXECUTION_DATE='2024-05-27T17:34:02.589937+00:00' AIRFLOW_CTX_TRY_NUMBER='1' AIRFLOW_CTX_DAG_RUN_ID='manual__2024-05-27T17:34:02.589937+00:00'
[2024-05-27T17:34:05.991+0000] {taskinstance.py:2698} ERROR - Task failed with exception
Traceback (most recent call last):
  File "/home/airflow/.local/lib/python3.8/site-packages/airflow/models/taskinstance.py", line 433, in _execute_task
    result = execute_callable(context=context, **execute_callable_kwargs)
  File "/home/airflow/.local/lib/python3.8/site-packages/airflow/operators/python.py", line 199, in execute
    return_value = self.execute_callable()
  File "/home/airflow/.local/lib/python3.8/site-packages/airflow/operators/python.py", line 216, in execute_callable
    return self.python_callable(*self.op_args, **self.op_kwargs)
  File "/opt/airflow/dags/tipico_etl.py", line 18, in run_tipico_etl
    df.to_csv(filename)
  File "/home/airflow/.local/lib/python3.8/site-packages/pandas/core/generic.py", line 3772, in to_csv
    return DataFrameRenderer(formatter).to_csv(
  File "/home/airflow/.local/lib/python3.8/site-packages/pandas/io/formats/format.py", line 1186, in to_csv
    csv_formatter.save()
  File "/home/airflow/.local/lib/python3.8/site-packages/pandas/io/formats/csvs.py", line 240, in save
    with get_handle(
  File "/home/airflow/.local/lib/python3.8/site-packages/pandas/io/common.py", line 737, in get_handle
    check_parent_directory(str(handle))
  File "/home/airflow/.local/lib/python3.8/site-packages/pandas/io/common.py", line 600, in check_parent_directory
    raise OSError(rf"Cannot save file into a non-existent directory: '{parent}'")
OSError: Cannot save file into a non-existent directory: 'data'
[2024-05-27T17:34:06.010+0000] {taskinstance.py:1138} INFO - Marking task as UP_FOR_RETRY. dag_id=tipico_dag, task_id=run_tipico_etl, execution_date=20240527T173402, start_date=20240527T173405, end_date=20240527T173406
[2024-05-27T17:34:06.026+0000] {standard_task_runner.py:107} ERROR - Failed to execute job 123 for task run_tipico_etl (Cannot save file into a non-existent directory: 'data'; 317)
[2024-05-27T17:34:06.071+0000] {local_task_job_runner.py:234} INFO - Task exited with return code 1
[2024-05-27T17:34:06.090+0000] {taskinstance.py:3280} INFO - 0 downstream tasks scheduled from follow-on schedule check
