[2024-05-31T13:33:11.506+0000] {taskinstance.py:1956} INFO - Dependencies all met for dep_context=non-requeueable deps ti=<TaskInstance: tipico_dag.load_data_to_redshift manual__2024-05-31T13:33:05.108981+00:00 [queued]>
[2024-05-31T13:33:11.518+0000] {taskinstance.py:1956} INFO - Dependencies all met for dep_context=requeueable deps ti=<TaskInstance: tipico_dag.load_data_to_redshift manual__2024-05-31T13:33:05.108981+00:00 [queued]>
[2024-05-31T13:33:11.519+0000] {taskinstance.py:2170} INFO - Starting attempt 1 of 2
[2024-05-31T13:33:11.535+0000] {taskinstance.py:2191} INFO - Executing <Task(PythonOperator): load_data_to_redshift> on 2024-05-31 13:33:05.108981+00:00
[2024-05-31T13:33:11.547+0000] {standard_task_runner.py:60} INFO - Started process 35393 to run task
[2024-05-31T13:33:11.552+0000] {standard_task_runner.py:87} INFO - Running: ['***', 'tasks', 'run', 'tipico_dag', 'load_data_to_redshift', 'manual__2024-05-31T13:33:05.108981+00:00', '--job-id', '499', '--raw', '--subdir', 'DAGS_FOLDER/tipico_dag.py', '--cfg-path', '/tmp/tmpy2iv76mu']
[2024-05-31T13:33:11.554+0000] {standard_task_runner.py:88} INFO - Job 499: Subtask load_data_to_redshift
[2024-05-31T13:33:11.617+0000] {task_command.py:423} INFO - Running <TaskInstance: tipico_dag.load_data_to_redshift manual__2024-05-31T13:33:05.108981+00:00 [running]> on host a71bb5ce980f
[2024-05-31T13:33:11.732+0000] {taskinstance.py:2480} INFO - Exporting env vars: AIRFLOW_CTX_DAG_OWNER='***' AIRFLOW_CTX_DAG_ID='tipico_dag' AIRFLOW_CTX_TASK_ID='load_data_to_redshift' AIRFLOW_CTX_EXECUTION_DATE='2024-05-31T13:33:05.108981+00:00' AIRFLOW_CTX_TRY_NUMBER='1' AIRFLOW_CTX_DAG_RUN_ID='manual__2024-05-31T13:33:05.108981+00:00'
[2024-05-31T13:33:11.774+0000] {logging_mixin.py:188} INFO -    Unnamed: 0  ...  eventMetadata
0           0  ...            NaN
1           1  ...            NaN

[2 rows x 22 columns]
[2024-05-31T13:33:11.787+0000] {logging_mixin.py:188} INFO - 2
[2024-05-31T13:33:11.787+0000] {logging_mixin.py:188} INFO - {'id': 71233, 'name': 'Kato M / Kichenok N', 'position': 'HOME', 'abbreviation': 'KKI'} ---------------- 0
[2024-05-31T13:33:11.788+0000] {logging_mixin.py:188} INFO - {'id': 39274, 'name': 'Saville D / Tomljanovic A', 'position': 'AWAY', 'abbreviation': 'STO'} ---------------- 0
[2024-05-31T13:33:11.789+0000] {logging_mixin.py:188} INFO - 2
[2024-05-31T13:33:11.790+0000] {logging_mixin.py:188} INFO - {'id': 86144, 'name': 'Jacquemot E / Tan H', 'position': 'HOME', 'abbreviation': 'JTA'} ---------------- 1
[2024-05-31T13:33:11.790+0000] {logging_mixin.py:188} INFO - {'id': 30924, 'name': 'Mihalikova T / Noskova L', 'position': 'AWAY', 'abbreviation': 'MNO'} ---------------- 1
[2024-05-31T13:33:11.879+0000] {base.py:83} INFO - Using connection ID 'redshift_default' for task execution.
[2024-05-31T13:33:12.793+0000] {logging_mixin.py:188} INFO - {814989}
[2024-05-31T13:33:12.794+0000] {taskinstance.py:2698} ERROR - Task failed with exception
Traceback (most recent call last):
  File "/home/airflow/.local/lib/python3.8/site-packages/pandas/core/indexes/base.py", line 3653, in get_loc
    return self._engine.get_loc(casted_key)
  File "pandas/_libs/index.pyx", line 147, in pandas._libs.index.IndexEngine.get_loc
  File "pandas/_libs/index.pyx", line 176, in pandas._libs.index.IndexEngine.get_loc
  File "pandas/_libs/hashtable_class_helper.pxi", line 7080, in pandas._libs.hashtable.PyObjectHashTable.get_item
  File "pandas/_libs/hashtable_class_helper.pxi", line 7088, in pandas._libs.hashtable.PyObjectHashTable.get_item
KeyError: 'eventName'

The above exception was the direct cause of the following exception:

Traceback (most recent call last):
  File "/home/airflow/.local/lib/python3.8/site-packages/airflow/models/taskinstance.py", line 433, in _execute_task
    result = execute_callable(context=context, **execute_callable_kwargs)
  File "/home/airflow/.local/lib/python3.8/site-packages/airflow/operators/python.py", line 199, in execute
    return_value = self.execute_callable()
  File "/home/airflow/.local/lib/python3.8/site-packages/airflow/operators/python.py", line 216, in execute_callable
    return self.python_callable(*self.op_args, **self.op_kwargs)
  File "/opt/airflow/dags/tipico_etl.py", line 208, in load_data_to_redshift
    '{row['eventName']}',
  File "/home/airflow/.local/lib/python3.8/site-packages/pandas/core/series.py", line 1007, in __getitem__
    return self._get_value(key)
  File "/home/airflow/.local/lib/python3.8/site-packages/pandas/core/series.py", line 1116, in _get_value
    loc = self.index.get_loc(label)
  File "/home/airflow/.local/lib/python3.8/site-packages/pandas/core/indexes/base.py", line 3655, in get_loc
    raise KeyError(key) from err
KeyError: 'eventName'
[2024-05-31T13:33:12.823+0000] {taskinstance.py:1138} INFO - Marking task as UP_FOR_RETRY. dag_id=tipico_dag, task_id=load_data_to_redshift, execution_date=20240531T133305, start_date=20240531T133311, end_date=20240531T133312
[2024-05-31T13:33:12.844+0000] {standard_task_runner.py:107} ERROR - Failed to execute job 499 for task load_data_to_redshift ('eventName'; 35393)
[2024-05-31T13:33:12.893+0000] {local_task_job_runner.py:234} INFO - Task exited with return code 1
[2024-05-31T13:33:12.913+0000] {taskinstance.py:3280} INFO - 0 downstream tasks scheduled from follow-on schedule check
